Traceback (most recent call last):
  File "C:\Users\antoi\anaconda3\envs\Python37\lib\site-packages\tensorflow_core\python\framework\ops.py", line 1619, in _create_c_op
    c_op = c_api.TF_FinishOperation(op_desc)
tensorflow.python.framework.errors_impl.InvalidArgumentError: Negative dimension size caused by subtracting 2 from 1 for 'max_pooling2d/MaxPool' (op: 'MaxPool') with input shapes: [?,1,1,16].

During handling of the above exception, another exception occurred:

Traceback (most recent call last):
  File "archi_random_9_v.py", line 42, in <module>
    keras.layers.Dense(84, activation='relu'),
  File "C:\Users\antoi\anaconda3\envs\Python37\lib\site-packages\tensorflow_core\python\training\tracking\base.py", line 457, in _method_wrapper
    result = method(self, *args, **kwargs)
  File "C:\Users\antoi\anaconda3\envs\Python37\lib\site-packages\tensorflow_core\python\keras\engine\sequential.py", line 116, in __init__
    self.add(layer)
  File "C:\Users\antoi\anaconda3\envs\Python37\lib\site-packages\tensorflow_core\python\training\tracking\base.py", line 457, in _method_wrapper
    result = method(self, *args, **kwargs)
  File "C:\Users\antoi\anaconda3\envs\Python37\lib\site-packages\tensorflow_core\python\keras\engine\sequential.py", line 203, in add
    output_tensor = layer(self.outputs[0])
  File "C:\Users\antoi\anaconda3\envs\Python37\lib\site-packages\tensorflow_core\python\keras\engine\base_layer.py", line 773, in __call__
    outputs = call_fn(cast_inputs, *args, **kwargs)
  File "C:\Users\antoi\anaconda3\envs\Python37\lib\site-packages\tensorflow_core\python\keras\layers\pooling.py", line 248, in call
    data_format=conv_utils.convert_data_format(self.data_format, 4))
  File "C:\Users\antoi\anaconda3\envs\Python37\lib\site-packages\tensorflow_core\python\ops\nn_ops.py", line 3875, in max_pool
    name=name)
  File "C:\Users\antoi\anaconda3\envs\Python37\lib\site-packages\tensorflow_core\python\ops\gen_nn_ops.py", line 5200, in max_pool
    data_format=data_format, name=name)
  File "C:\Users\antoi\anaconda3\envs\Python37\lib\site-packages\tensorflow_core\python\framework\op_def_library.py", line 742, in _apply_op_helper
    attrs=attr_protos, op_def=op_def)
  File "C:\Users\antoi\anaconda3\envs\Python37\lib\site-packages\tensorflow_core\python\framework\func_graph.py", line 595, in _create_op_internal
    compute_device)
  File "C:\Users\antoi\anaconda3\envs\Python37\lib\site-packages\tensorflow_core\python\framework\ops.py", line 3322, in _create_op_internal
    op_def=op_def)
  File "C:\Users\antoi\anaconda3\envs\Python37\lib\site-packages\tensorflow_core\python\framework\ops.py", line 1786, in __init__
    control_input_ops)
  File "C:\Users\antoi\anaconda3\envs\Python37\lib\site-packages\tensorflow_core\python\framework\ops.py", line 1622, in _create_c_op
    raise ValueError(str(e))
ValueError: Negative dimension size caused by subtracting 2 from 1 for 'max_pooling2d/MaxPool' (op: 'MaxPool') with input shapes: [?,1,1,16].
