Traceback (most recent call last):
  File "archi_random_10_v.py", line 40, in <module>
    model.fit(train_x, train_y, epochs=5, validation_data=(val_x, val_y))
  File "C:\Users\antoi\anaconda3\envs\Python37\lib\site-packages\tensorflow_core\python\keras\engine\training.py", line 819, in fit
    use_multiprocessing=use_multiprocessing)
  File "C:\Users\antoi\anaconda3\envs\Python37\lib\site-packages\tensorflow_core\python\keras\engine\training_v2.py", line 342, in fit
    total_epochs=epochs)
  File "C:\Users\antoi\anaconda3\envs\Python37\lib\site-packages\tensorflow_core\python\keras\engine\training_v2.py", line 128, in run_one_epoch
    batch_outs = execution_function(iterator)
  File "C:\Users\antoi\anaconda3\envs\Python37\lib\site-packages\tensorflow_core\python\keras\engine\training_v2_utils.py", line 98, in execution_function
    distributed_function(input_fn))
  File "C:\Users\antoi\anaconda3\envs\Python37\lib\site-packages\tensorflow_core\python\eager\def_function.py", line 568, in __call__
    result = self._call(*args, **kwds)
  File "C:\Users\antoi\anaconda3\envs\Python37\lib\site-packages\tensorflow_core\python\eager\def_function.py", line 632, in _call
    return self._stateless_fn(*args, **kwds)
  File "C:\Users\antoi\anaconda3\envs\Python37\lib\site-packages\tensorflow_core\python\eager\function.py", line 2363, in __call__
    return graph_function._filtered_call(args, kwargs)  # pylint: disable=protected-access
  File "C:\Users\antoi\anaconda3\envs\Python37\lib\site-packages\tensorflow_core\python\eager\function.py", line 1611, in _filtered_call
    self.captured_inputs)
  File "C:\Users\antoi\anaconda3\envs\Python37\lib\site-packages\tensorflow_core\python\eager\function.py", line 1692, in _call_flat
    ctx, args, cancellation_manager=cancellation_manager))
  File "C:\Users\antoi\anaconda3\envs\Python37\lib\site-packages\tensorflow_core\python\eager\function.py", line 545, in call
    ctx=ctx)
  File "C:\Users\antoi\anaconda3\envs\Python37\lib\site-packages\tensorflow_core\python\eager\execute.py", line 67, in quick_execute
    six.raise_from(core._status_to_exception(e.code, message), None)
  File "<string>", line 3, in raise_from
tensorflow.python.framework.errors_impl.UnknownError:  Failed to get convolution algorithm. This is probably because cuDNN failed to initialize, so try looking to see if a warning log message was printed above.
	 [[node sequential/conv2d/Conv2D (defined at archi_random_10_v.py:40) ]] [Op:__inference_distributed_function_671]

Function call stack:
distributed_function

